<?xml version="1.0" ?>
<robot
  xmlns:xacro="http://www.ros.org/wiki/xacro" 
  xmlns:sensor="http://playerstage.sourceforge.net/gazebo/xmlschema/#sensor"
  xmlns:controller="http://playerstage.sourceforge.net/gazebo/xmlschema/#controller"
  xmlns:interface="http://playerstage.sourceforge.net/gazebo/xmlschema/#interface"
  name="mobile_hubo_omniWH">

  <!-- Constants for robot dimensions -->
  <xacro:property name="PI" value="3.1415926535897931"/>


  <!-- Wheels -->
  <!-- in kg-->
  <!-- Defining the colors used in this robot -->
  <material name="Black">
    <color rgba="0.0 0.0 0.0 1.0"/>
  </material>
  <material name="Red">
    <color rgba="0.8 0.0 0.0 1.0"/>
  </material>
  <material name="White">
    <color rgba="1.0 1.0 1.0 1.0"/>
  </material>
  <material name="Blue">
    <color rgba="0.0 0.0 0.8 1.0"/>
  </material>


   <link name="world"/>

<!--    <joint name="x_axis_joint" type="prismatic">-->
    <joint name="RHY" type="prismatic">
        <origin xyz="0 0 0.001" rpy="0.0 0.0 0.0"/>
        <parent link="world" />
        <child link="x_axis_link" />
        <axis xyz="1 0 0" />
        <limit effort="1000000" lower="-10.0" upper="10.0" velocity="1" />
        <dynamics damping="1.0" friction = "100000"/>
    </joint>

    <link name="x_axis_link">
<!--
       <visual>
            <origin xyz="0 0 0.005" rpy="0 0 0" />
            <geometry>
                <cylinder radius="0.2" length="0.01"/>
            </geometry>
        </visual>
 
        <collision>
            <origin xyz="0 0 0.005" rpy="0 0 0" />
            <geometry>
                <cylinder radius="0.2" length="0.01"/>
            </geometry>
        </collision>
-->
 	<inertial>
            <origin xyz="0 0 0.005" rpy="0 0 0" />
            <mass value="1000" />
            <inertia ixx="1.00000833e1" ixy="0.0" ixz="0.0" iyy="1.00000833e1" iyz="0.0" izz="2e1"/>
        </inertial>
	</link>


    <gazebo reference="x_axis_link">
        <mu1>10.0</mu1>
        <mu2>10.0</mu2>
        <material>Gazebo/Red</material>
    </gazebo>

<!--    <joint name="y_axis_joint" type="prismatic">-->
    <joint name="RHR" type="prismatic">
        <origin xyz="0 0 0.01" rpy="0.0 0.0 0.0"/>
        <parent link="x_axis_link" />
        <child link="y_axis_link" />
        <axis xyz="0 1 0" />
        <limit effort="1000000" lower="-10.0" upper="10.0" velocity="1" />
        <dynamics damping="1.0" friction = "100000"/>
    </joint>

    <link name="y_axis_link">
<!--
        <visual>
            <origin xyz="0 0 0.005" rpy="0 0 0" />
            <geometry>
                <cylinder radius="0.2" length="0.01"/>
            </geometry>
        </visual>

        <collision>
            <origin xyz="0 0 0.005" rpy="0 0 0" />
            <geometry>
                <cylinder radius="0.2" length="0.01"/>
            </geometry>
        </collision>
-->
 	<inertial>
            <origin xyz="0 0 0.005" rpy="0 0 0" />
            <mass value="1000" />
            <inertia ixx="1.00000833e1" ixy="0.0" ixz="0.0" iyy="1.00000833e1" iyz="0.0" izz="2e1"/>
        </inertial>
    </link>

    <gazebo reference="y_axis_link">
        <mu1>10.0</mu1>
        <mu2>10.0</mu2>
        <material>Gazebo/Green</material>
        <self_collide>0</self_collide>
    </gazebo>

    <joint name="RHP" type="continuous">
        <parent link="y_axis_link"/>
        <child link="base_footprint"/>
        <origin xyz="0 0 0.01" rpy="0 0 0"/>
    	<axis xyz="0 0 1" />
    	<limit effort="10000000" velocity="1.0"/>
    	<dynamics damping="2" friction="100000" />
    </joint>

  <link name="base_footprint">
<!--    <visual>
        <origin xyz="0 0 0.025" rpy="0 0 0" />
        <geometry>
            <cylinder radius="0.05" length="0.05"/>
        </geometry>
    </visual>
-->
    <collision>
        <origin xyz="0 0 0.025" rpy="0 0 0" />
        <geometry>
           <cylinder radius="0.05" length="0.05"/>
        </geometry>
    </collision>
    <inertial>
        <origin xyz="0 0 0.025" rpy="0 0 0" />
        <mass value="1000" />
        <inertia ixx="833.3333e-3" ixy="0.0" ixz="0.0" iyy="833.333e-3" iyz="0.0" izz="1250e-3"/>
    </inertial>
  </link>

<!--  <link name="base_footprint">
    <visual>
      <origin rpy="0 0 0" xyz="0 0 0.005"/>
      <geometry>
        <box size="0.01 0.01 0.01"/>
      </geometry>
    </visual>
    <inertial>
      <mass value="1000"/>
      <origin xyz="0 0 0.005"/>
      <inertia ixx="0.167e-3" ixy="0.0" ixz="0.0" iyy="0.167e-3" iyz="0.0" izz="0.167e-3"/>
    </inertial>
    <collision>
      <origin xyz="0 0 0.005" rpy="0 0 0"/>
      <geometry>
        <box size="0.01 0.01 0.01"/>
      </geometry>
    </collision>
  </link>-->

  <gazebo reference="base_footprint">
    <turnGravityOff>false</turnGravityOff>
  </gazebo>

  <joint name="base_footprint_joint" type="fixed">
    <origin rpy="0 0 0" xyz="0 0.0 0.11"/>
    <parent link="base_footprint"/>
    <child link="Body_WHBase_link"/>
  </joint>


  <!--BODY TORSO-->
  <joint name="WST" type="revolute">
    <origin
      xyz="0 0 0.692"
      rpy="0 0 0" />
    <parent
      link="Body_WHBase_link" />
    <child
      link="Body_TORSO" />
    <axis
      xyz="0 0 1" />
    <limit effort="100000" velocity="100" lower="-3.14" upper="3.14" />
    <dynamics damping="30" friction="5" />
  </joint>

  <link name="Body_TORSO">
    <inertial>
      <origin
        xyz="0.000373 0.000832 0.360257"
        rpy="0 -0 0" />
      <mass
        value="18.236" />
      <inertia
        ixx="0.19794"
        ixy="6.4e-05"
        ixz="-0.001125"
        iyy="0.155811"
        iyz="0.000284"
        izz="0.117584" />
    </inertial>
    <visual>
      <origin
        xyz="0 0 -0.203"
        rpy="0 0 0" />
      <geometry>
        <mesh
          filename="package://hubo_plugin/meshes/Body_TORSO.STL" />
      </geometry>
      <material
        name="">
        <color
          rgba="0.79216 0.81961 0.93333 1" />
      </material>
    </visual>
    <collision>
      <origin
        xyz="0 0 -0.203"
        rpy="0 0 0" />
      <geometry>
        <mesh
          filename="package://hubo_plugin/meshes/Body_TORSO_col.STL" />
      </geometry>
    </collision>
  </link>


<!-- LEFT ARM -->
<!-- LEFT ARM -->
<!-- LEFT ARM -->
  <joint name="LSP" type="revolute">
    <origin
      xyz="0 0.242 0.253"
      rpy="0 -0 0" />
    <parent
      link="Body_TORSO" />
    <child
      link="Body_LSP" />
    <axis
      xyz="0 1 0" />
    <limit effort="10000000" velocity="100.0" lower="-5" upper="5" />
    <dynamics damping="15" friction="2" />
  </joint>

  <link name="Body_LSP">
    <inertial>
      <origin
        xyz="0.015596 -0.052409 0"
        rpy="0 0 0" />
      <mass
        value="1.6" />
      <inertia
        ixx="0.005195"
        ixy="0.001333"
        ixz="1e-08"
        iyy="0.004409"
        iyz="0.0"
        izz="0.007234" />
    </inertial>
    <visual>
      <origin
        xyz="0 0 0"
        rpy="0 0 0" />
      <geometry>
        <mesh
          filename="package://hubo_plugin/meshes/Body_LSP.STL" />
      </geometry>
      <material
        name="">
        <color
          rgba="0.79216 0.81961 0.93333 1" />
      </material>
    </visual>
    <collision>
      <origin
        xyz="0 0 0"
        rpy="0 0 0" />
      <geometry>
        <mesh
          filename="package://hubo_plugin/meshes/Body_LSP_col.STL" />
      </geometry>
    </collision>
  </link>

 <joint name="LSR" type="revolute">
    <origin
      xyz="0 0 0"
      rpy="0 0 0" />
    <parent
      link="Body_LSP" />
    <child
      link="Body_LSR" />
    <axis
      xyz="1 0 0" />
    <limit effort="10000000" velocity="100.0" lower="-5.14" upper="5.14" />
    <dynamics damping="15" friction="2" />
  </joint>

  <link name="Body_LSR">
    <inertial>
      <origin
        xyz="-0.003104 0.000106 -0.013013"
        rpy="0 -0 0" />
      <mass
        value="1.427" />
      <inertia
        ixx="0.003163"
        ixy="6e-06"
        ixz="-0.000211"
        iyy="0.003689"
        iyz="0.0"
        izz="0.001909" />
    </inertial>
    <visual>
      <origin
        xyz="0 0 0"
        rpy="0 0 0" />
      <geometry>
        <mesh
          filename="package://hubo_plugin/meshes/Body_LSR.STL" />
      </geometry>
      <material
        name="">
        <color
          rgba="0.79216 0.81961 0.93333 1" />
      </material>
    </visual>
    <collision>
      <origin
        xyz="0 0 0"
        rpy="0 0 0" />
      <geometry>
        <mesh
          filename="package://hubo_plugin/meshes/Body_LSR_col.STL" />
      </geometry>
    </collision>
  </link>

  <joint name="LSY" type="revolute">
    <origin
      xyz="0 0 0"
      rpy="0 0 0" />
    <parent
      link="Body_LSR" />
    <child
      link="Body_LSY" />
    <axis
      xyz="0 0 1" />
    <limit effort="10000000" velocity="100.0" lower="-5" upper="5" />
    <dynamics damping="5" friction="2" />
  </joint>

  <link name="Body_LSY">
    <inertial>
      <origin
        xyz="0.035284 -0.242 -0.87969"
        rpy="0 0 0" />
      <mass
        value="2.35838" />
      <inertia
        ixx="0.024139"
        ixy="0.000334"
        ixz="-0.003948"
        iyy="0.024861"
        iyz="-0.001103"
        izz="0.003447" />
    </inertial>
    <visual>
      <origin
        xyz="0 0 0"
        rpy="0 0 0" />
      <geometry>
        <mesh
          filename="package://hubo_plugin/meshes/Body_LSY.STL" />
      </geometry>
      <material
        name="">
        <color
          rgba="0.79216 0.81961 0.93333 1" />
      </material>
    </visual>
    <collision>
      <origin
        xyz="0 0 0"
        rpy="0 0 0" />
      <geometry>
        <mesh
          filename="package://hubo_plugin/meshes/Body_LSY_col.STL" />
      </geometry>
    </collision>
  </link>

  <joint name="LEB" type="revolute">
    <origin
      xyz="0.035 0 -0.350"
      rpy="0 0 0" />
    <parent
      link="Body_LSY" />
    <child
      link="Body_LEB" />
    <axis
      xyz="0 1 0" />
    <limit effort="10000000" velocity="100.0" lower="-5" upper="5" />
    <dynamics damping="8" friction="2" />
  </joint>

  <link name="Body_LEB">
    <inertial>
      <origin
        xyz="-0.019775 0.004924 -0.041836"
        rpy="0 0 0" />
      <mass
        value="0.409464" />
      <inertia
        ixx="0.001031"
        ixy="4e-05"
        ixz="0.000277"
        iyy="0.001163"
        iyz="8.5e-05"
        izz="0.00056" />
    </inertial>
    <visual>
      <origin
        xyz="0 0 0"
        rpy="0 0 0" />
      <geometry>
        <mesh
          filename="package://hubo_plugin/meshes/Body_LEB.STL" />
      </geometry>
      <material
        name="">
        <color
          rgba="0.79216 0.81961 0.93333 1" />
      </material>
    </visual>
    <collision>
      <origin
        xyz="0 0 0"
        rpy="0 0 0" />
      <geometry>
        <mesh
          filename="package://hubo_plugin/meshes/Body_LEB_col.STL" />
      </geometry>
    </collision>
  </link>

  <joint name="LWY" type="revolute">
    <origin
      xyz="-0.035 0 -0.34"
      rpy="0 0 0" />
    <parent
      link="Body_LEB" />
    <child
      link="Body_LWY" />
    <axis
      xyz="0 0 1" />
    <limit effort="10000000" velocity="100.0" lower="-5" upper="5" />
    <dynamics damping="0.8" friction="50" />
  </joint>

  <link name="Body_LWY">
    <inertial>
      <origin
        xyz="5.4e-05 0.001779 0.134651"
        rpy="0 0 0" />
      <mass
        value="1.47" />
      <inertia
        ixx="0.01302"
        ixy="-1e-05"
        ixz="4e-5"
        iyy="0.012803"
        iyz="-0.000388"
        izz="0.000862" />
    </inertial>
    <visual>
      <origin
        xyz="0 0 0"
        rpy="0 0 0" />
      <geometry>
        <mesh
          filename="package://hubo_plugin/meshes/Body_LWY.STL" />
      </geometry>
      <material
        name="">
        <color rgba="0.79216 0.81961 0.93333 1" />
      </material>
    </visual>
    <collision>
      <origin
        xyz="0 0 0"
        rpy="0 0 0" />
      <geometry>
        <mesh
          filename="package://hubo_plugin/meshes/Body_LWY_col.STL" />
      </geometry>
    </collision>
  </link>

  <joint name="LWP" type="revolute">
    <origin
      xyz="0 0 0"
      rpy="0 0 0" />
    <parent
      link="Body_LWY" />
    <child
      link="Body_LWP" />
    <axis
      xyz="0 1 0" />
    <limit effort="10000000" velocity="100.0" lower="-5" upper="5" />
    <dynamics damping="0.1" friction="0.2" />
  </joint>

  <link name="Body_LWP">
    <inertial>
      <origin
        xyz="1.7e-05 0.011876 -0.003359"
        rpy="0 0 0" />
      <mass
        value="0.158865" />
      <inertia
        ixx="7.2e-04"
        ixy="1.0e-06"
        ixz="1.0e-06"
        iyy="6.5e-04"
        iyz="6.0e-05"
        izz="6.5e-04" />
    </inertial>
    <visual>
      <origin
        xyz="0 0 0"
        rpy="0 0 0" />
      <geometry>
        <mesh
          filename="package://hubo_plugin/meshes/Body_LWP.STL" />
      </geometry>
      <material
        name="">
        <color
          rgba="0.79216 0.81961 0.93333 1" />
      </material>
    </visual>
    <collision>
      <origin
        xyz="0 0 0"
        rpy="0 0 0" />
      <geometry>
        <mesh
          filename="package://hubo_plugin/meshes/Body_LWP_col.STL" />
      </geometry>
    </collision>
  </link>

  <joint name="LWFT" type="prismatic">
    <origin
      xyz="0 0 -0.0326"
      rpy="0 0 0" />
    <parent
      link="Body_LWP" />
    <child
      link="Body_LWFT" />
    <axis
      xyz="0 0 1" />
    <limit effort="1000000" velocity="1000000.0" lower="-0" upper="0" />
    <dynamics damping="1" friction="1" />
  </joint>

  <gazebo reference = "LWFT">
    <provide_feedback> true </provide_feedback>
    <physics>
      <ode>
        <provide_feedback>true</provide_feedback>
      </ode>
    </physics>
  </gazebo>

  <link name="Body_LWFT">
    <inertial>
      <origin
        xyz="-1.2e-05 -3e-06 -0.017752"
        rpy="0 0 0" />
      <mass
        value="0.016659" />
      <inertia
        ixx="2.0e-05"
        ixy="1.0e-06"
        ixz="1.0e-06"
        iyy="1.85e-05"
        iyz="1.0e-06"
        izz="3.33e-05" />
    </inertial>
    <visual>
      <origin
        xyz="0 0 0"
        rpy="0 0 0" />
      <geometry>
        <mesh
          filename="package://hubo_plugin/meshes/Body_LWFT.STL" />
      </geometry>
      <material
        name="">
        <color
          rgba="0.79216 0.81961 0.93333 1" />
      </material>
    </visual>
    <collision>
      <origin
        xyz="0 0 0"
        rpy="0 0 0" />
      <geometry>
        <mesh
          filename="package://hubo_plugin/meshes/Body_LWFT_col.STL" />
      </geometry>
    </collision>

      <sensor name='FT_LWFT' type='contact'>
        <contact>
          <collision>Body_LWFT_collision</collision>
        </contact>
      </sensor>

  </link>



  <joint name="LWY2" type="revolute">
    <origin
      xyz="0 0 0.0326"
      rpy="0 0 0" />
    <parent
      link="Body_LWFT" />
    <child
      link="Body_LF1" />
    <axis
      xyz="0 0 1" />
    <limit effort="10000000" velocity="100.0" lower="-5" upper="5" />
    <dynamics damping="0.1" friction="1" />
  </joint>


  <link name = "Body_LF1">
   <inertial>
      <origin
        xyz="0.00350179 0.00500094 -0.108683" rpy="0 0 0" />
      <mass value="0.894667" />
      <inertia
        ixx="0.00087045"
        ixy="-1.448e-05"
        ixz="-1.064e-05"
        iyy="0.00103972"
        iyz="-7.89e-06"
        izz="0.00095329" />
    </inertial>
    <visual> 
      <origin
        xyz="0 0 0.0" rpy="0 0 0" />
      <geometry>
        <mesh
          filename="package://hubo_plugin/meshes/Body_LF1.STL" />
      </geometry>
      <material
        name="">
        <color
          rgba="0.79216 0.81961 0.93333 1" />
      </material>
    </visual>
    <collision>
      <origin
        xyz="0 0 0" rpy="0 0 0" />
      <geometry>
        <mesh
          filename="package://hubo_plugin/meshes/Body_LF1_col.STL" />
      </geometry>
    </collision>
  </link>


<!--finger friction-->
  <gazebo reference="Body_LF2_a1">
    <mu1 value="1.0"/>
    <mu2 value="1.0"/>
    <kp value="10000000.0"/>
    <kd value="1.0"/>
    <fdir1 value="1 0 0"/>
    <min_depth value = "0.001"/>
    <max_vel value = "0.1"/>
    <turnGravityOff>false</turnGravityOff>
  </gazebo>

  <gazebo reference="Body_LF2_a2">
    <mu1 value="1.0"/>
    <mu2 value="1.0"/>
    <kp value="10000000.0"/>
    <kd value="1.0"/>
    <fdir1 value="1 0 0"/>
    <min_depth value = "0.001"/>
    <max_vel value = "0.1"/>
    <turnGravityOff>false</turnGravityOff>
  </gazebo>

  <gazebo reference="Body_LF2_a3">
    <mu1 value="1.0"/>
    <mu2 value="1.0"/>
    <kp value="10000000.0"/>
    <kd value="1.0"/>
    <fdir1 value="1 0 0"/>
    <min_depth value = "0.001"/>
    <max_vel value = "0.1"/>
    <turnGravityOff>false</turnGravityOff>
  </gazebo>

  <gazebo reference="Body_LF2_b1">
    <mu1 value="1.0"/>
    <mu2 value="1.0"/>
    <kp value="10000000.0"/>
    <kd value="1.0"/>
    <fdir1 value="1 0 0"/>
    <min_depth value = "0.001"/>
    <max_vel value = "0.1"/>
    <turnGravityOff>false</turnGravityOff>
  </gazebo>

  <gazebo reference="Body_LF2_b2">
    <mu1 value="1.0"/>
    <mu2 value="1.0"/>
    <kp value="10000000.0"/>
    <kd value="1.0"/>
    <fdir1 value="1 0 0"/>
    <min_depth value = "0.001"/>
    <max_vel value = "0.1"/>
    <turnGravityOff>false</turnGravityOff>
  </gazebo>

  <gazebo reference="Body_LF2_b3">
    <mu1 value="1.0"/>
    <mu2 value="1.0"/>
    <kp value="10000000.0"/>
    <kd value="1.0"/>
    <fdir1 value="1 0 0"/>
    <min_depth value = "0.001"/>
    <max_vel value = "0.1"/>
    <turnGravityOff>false</turnGravityOff>
  </gazebo>

  <gazebo reference="Body_LF2_c1">
    <mu1 value="1.0"/>
    <mu2 value="1.0"/>
    <kp value="10000000.0"/>
    <kd value="1.0"/>
    <fdir1 value="1 0 0"/>
    <min_depth value = "0.001"/>
    <max_vel value = "0.1"/>
    <turnGravityOff>false</turnGravityOff>
  </gazebo>

  <gazebo reference="Body_LF2_c2">
    <mu1 value="1.0"/>
    <mu2 value="1.0"/>
    <kp value="10000000.0"/>
    <kd value="1.0"/>
    <fdir1 value="1 0 0"/>
    <min_depth value = "0.001"/>
    <max_vel value = "0.1"/>
    <turnGravityOff>false</turnGravityOff>
  </gazebo>

  <gazebo reference="Body_LF2_c3">
    <mu1 value="1.0"/>
    <mu2 value="1.0"/>
    <kp value="10000000.0"/>
    <kd value="1.0"/>
    <fdir1 value="1 0 0"/>
    <min_depth value = "0.001"/>
    <max_vel value = "0.1"/>
    <turnGravityOff>false</turnGravityOff>
  </gazebo>



<!-- LEFT HAND -->
<!-- LEFT HAND -->
<!-- LEFT HAND -->

  <joint name="LHAND_a1" type="revolute">
    <origin
      xyz="0.02498 -0.023 -0.1471"
      rpy="0 0 0" />
    <parent
      link="Body_LF1" />
    <child
      link="Body_LF2_a1" />
    <axis
      xyz="0 1 0" />
    <limit effort="100000" velocity="1.0" lower="0" upper="1.4708" />
    <dynamics damping="0.0003" friction="0.1" />
  </joint>

  <link name="Body_LF2_a1">
    <inertial>
      <origin
        xyz="-0.0228526 -0.00016373 -0.0095261"
        rpy="0 0 0" />
      <mass
        value="0.038683" />
      <inertia
        ixx="1.143e-04"
        ixy="7e-06"
        ixz="-6.53e-05"
        iyy="2.17e-04"
        iyz="-1e-05"
        izz="1.314e-04" />
    </inertial>
    <visual>
      <origin
        xyz="0 0 0"
        rpy="0 0 0" />
      <geometry>
        <mesh
          filename="package://hubo_plugin/meshes/Body_LF2_a1.STL" />
      </geometry>
      <material
        name="">
        <color
          rgba="0.79216 0.81961 0.93333 1" />
      </material>
    </visual>
    <collision>
      <origin
        xyz="0 0 0"
        rpy="0 0 0" />
      <geometry>
        <mesh
          filename="package://hubo_plugin/meshes/Body_LF2_a1_col.STL" />
      </geometry>
    </collision>
  </link>

  <joint name="LHAND_a2" type="revolute">
    <origin
      xyz="0.03889 0 -0.0388"
      rpy="0 0.7854 0" />
    <parent
      link="Body_LF2_a1" />
    <child
      link="Body_LF2_a2" />
    <axis
      xyz="0 1 0" />
    <limit effort="100000" velocity="100.0" lower="0" upper="1.4708" />
    <dynamics damping="0.0003" friction="0.1" />
  </joint>

  <link name="Body_LF2_a2">
    <inertial>
      <origin
        xyz="0.0183473 -5.73e-06 0.00742064"
        rpy="0 0 0" />
      <mass
        value="0.021949" />
      <inertia
        ixx="2.31e-05"
        ixy="9e-06"
        ixz="-4.6e-06"
        iyy="7.09e-05"
        iyz="-5e-06"
        izz="6.69e-05" />
    </inertial>
    <visual>
      <origin
        xyz="0 0 0"
        rpy="0 0 0" />
      <geometry>
        <mesh
          filename="package://hubo_plugin/meshes/Body_LF2_a2.STL" />
      </geometry>
      <material
        name="">
        <color
          rgba="0.79216 0.81961 0.93333 1" />
      </material>
    </visual>
    <collision>
      <origin
        xyz="0 0 0"
        rpy="0 0 0" />
      <geometry>
        <mesh
          filename="package://hubo_plugin/meshes/Body_LF2_a3_col.STL" />
      </geometry>
    </collision>
  </link>

  <joint name="LHAND_a3" type="revolute">
    <origin
      xyz="0.04 0 0"
      rpy="0 0 0" />
    <parent
      link="Body_LF2_a2" />
    <child
      link="Body_LF2_a3" />
    <axis
      xyz="0 1 0" />
    <limit effort="100000" velocity="100.0" lower="0" upper="1.4708" />
    <dynamics damping="0.0003" friction="0.1" />
  </joint>

  <link name="Body_LF2_a3">
    <inertial>
      <origin
        xyz="0.00112468 -3.724e-05 0.00681838"
        rpy="0 0 0" />
      <mass
        value="0.0115" />
      <inertia
        ixx="7.2e-05"
        ixy="1e-06"
        ixz="2.9e-05"
        iyy="1.67e-05"
        iyz="1e-06"
        izz="1.84e-05" />
    </inertial>
    <visual>
      <origin
        xyz="0 0 0"
        rpy="0 0 0" />
      <geometry>
        <mesh
          filename="package://hubo_plugin/meshes/Body_LF2_a3.STL" />
      </geometry>
      <material
        name="">
        <color
          rgba="0.79216 0.81961 0.93333 1" />
      </material>
    </visual>
    <collision>
      <origin
        xyz="0 0 0"
        rpy="0 0 0" />
      <geometry>
        <mesh
          filename="package://hubo_plugin/meshes/Body_RF2_a3_col.STL" />
      </geometry>
    </collision>
  </link>


  <joint name="LHAND_b1" type="revolute">
    <origin
      xyz="0.02498 0.0232 -0.1471"
      rpy="0 0 0" />
    <parent
      link="Body_LF1" />
    <child
      link="Body_LF2_b1" />
    <axis
      xyz="0 1 0" />
    <limit effort="100000" velocity="100.0" lower="0" upper="1.4708" />
    <dynamics damping="0.0003" friction="0.1" />
  </joint>

  <link name="Body_LF2_b1">
    <inertial>
      <origin
        xyz="-0.0228526 -0.00016373 -0.0095261"
        rpy="0 0 0" />
      <mass
        value="0.038683" />
      <inertia
        ixx="1.143e-04"
        ixy="7e-06"
        ixz="-6.53e-05"
        iyy="2.17e-04"
        iyz="-1e-05"
        izz="1.314e-04" />
    </inertial>
    <visual>
      <origin
        xyz="0 0 0"
        rpy="0 0 0" />
      <geometry>
        <mesh
          filename="package://hubo_plugin/meshes/Body_LF2_b1.STL" />
      </geometry>
      <material
        name="">
        <color
          rgba="0.79216 0.81961 0.93333 1" />
      </material>
    </visual>
    <collision>
      <origin
        xyz="0 0 0"
        rpy="0 0 0" />
      <geometry>
        <mesh
          filename="package://hubo_plugin/meshes/Body_LF2_b1_col.STL" />
      </geometry>
    </collision>
  </link>

  <joint name="LHAND_b2" type="revolute">
    <origin
      xyz="0.03889 0 -0.0388"
      rpy="0 0.7854 0" />
    <parent
      link="Body_LF2_b1" />
    <child
      link="Body_LF2_b2" />
    <axis
      xyz="0 1 0" />
    <limit effort="100000" velocity="1.0" lower="0" upper="1.4708" />
    <dynamics damping="0.0003" friction="0.1" />
  </joint>

  <link name="Body_LF2_b2">
    <inertial>
      <origin
        xyz="0.0183473 -5.73e-06 0.00742064"
        rpy="0 0 0" />
      <mass
        value="0.021949" />
      <inertia
        ixx="2.31e-05"
        ixy="9e-06"
        ixz="-4.6e-06"
        iyy="7.09e-05"
        iyz="-5e-06"
        izz="6.69e-05" />
    </inertial>
    <visual>
      <origin
        xyz="0 0 0"
        rpy="0 0 0" />
      <geometry>
        <mesh
          filename="package://hubo_plugin/meshes/Body_LF2_b2.STL" />
      </geometry>
      <material
        name="">
        <color
          rgba="0.79216 0.81961 0.93333 1" />
      </material>
    </visual>
    <collision>
      <origin
        xyz="0 0 0"
        rpy="0 0 0" />
      <geometry>
        <mesh
          filename="package://hubo_plugin/meshes/Body_LF2_b2_col.STL" />
      </geometry>
    </collision>
  </link>

  <joint name="LHAND_b3" type="revolute">
    <origin
      xyz="0.04 0 0"
      rpy="0 0 0" />
    <parent
      link="Body_LF2_b2" />
    <child
      link="Body_LF2_b3" />
    <axis
      xyz="0 1 0" />
    <limit effort="100000" velocity="100.0" lower="0" upper="1.4708" />
    <dynamics damping="0.0003" friction="0.1" />
  </joint>

  <link name="Body_LF2_b3">
    <inertial>
      <origin
        xyz="0.00112468 -3.724e-05 0.00681838"
        rpy="0 0 0" />
      <mass
        value="0.0115" />
      <inertia
        ixx="7.2e-05"
        ixy="1e-06"
        ixz="2.9e-05"
        iyy="1.67e-05"
        iyz="1e-06"
        izz="1.84e-05" />
    </inertial>
    <visual>
      <origin
        xyz="0 0 0"
        rpy="0 0 0" />
      <geometry>
        <mesh
          filename="package://hubo_plugin/meshes/Body_LF2_b3.STL" />
      </geometry>
      <material
        name="">
        <color
          rgba="0.79216 0.81961 0.93333 1" />
      </material>
    </visual>
    <collision>
      <origin
        xyz="0 0 0"
        rpy="0 0 0" />
      <geometry>
        <mesh
          filename="package://hubo_plugin/meshes/Body_LF2_b3_col.STL" />
      </geometry>
    </collision>
  </link>


  <joint name="LHAND_c1" type="revolute">
    <origin
      xyz="-0.02502 0 -0.1471"
      rpy="0 0 0" />
    <parent
      link="Body_LF1" />
    <child
      link="Body_LF2_c1" />
    <axis
      xyz="0 -1 0" />
    <limit effort="100000" velocity="100.0" lower="0" upper="1.4708" />
    <dynamics damping="0.0003" friction="0.1" />
  </joint>

  <link name="Body_LF2_c1">
    <inertial>
      <origin
        xyz="-0.0228526 0.00016373 -0.0095261"
        rpy="0 0 0" />
      <mass
        value="0.038683" />
      <inertia
        ixx="1.143e-04"
        ixy="7e-06"
        ixz="-6.53e-05"
        iyy="2.17e-04"
        iyz="-1e-05"
        izz="1.314e-04" />
    </inertial>
    <visual>
      <origin
        xyz="0 0 0"
        rpy="0 0 0" />
      <geometry>
        <mesh
          filename="package://hubo_plugin/meshes/Body_LF2_c1.STL" />
      </geometry>
      <material
        name="">
        <color
          rgba="0.79216 0.81961 0.93333 1" />
      </material>
    </visual>
    <collision>
      <origin
        xyz="0 0 0"
        rpy="0 0 0" />
      <geometry>
        <mesh
          filename="package://hubo_plugin/meshes/Body_LF2_c1_col.STL" />
      </geometry>
    </collision>
  </link>

  <joint name="LHAND_c2" type="revolute">
    <origin
      xyz="-0.03889 0 -0.0388"
      rpy="0 -0.7854 0" />
    <parent
      link="Body_LF2_c1" />
    <child
      link="Body_LF2_c2" />
    <axis
      xyz="0 -1 0" />
    <limit effort="100000" velocity="100.0" lower="0" upper="1.4708" />
    <dynamics damping="0.0003" friction="0.1" />
  </joint>

  <link name="Body_LF2_c2">
    <inertial>
      <origin
        xyz="-0.0183473 5.73e-06 0.00742064"
        rpy="0 0 0" />
      <mass
        value="0.021949" />
      <inertia
        ixx="2.31e-05"
        ixy="9e-06"
        ixz="-4.6e-06"
        iyy="7.09e-05"
        iyz="-5e-06"
        izz="6.69e-05" />
    </inertial>
    <visual>
      <origin
        xyz="0 0 0"
        rpy="0 0 0" />
      <geometry>
        <mesh
          filename="package://hubo_plugin/meshes/Body_LF2_c2.STL" />
      </geometry>
      <material
        name="">
        <color
          rgba="0.79216 0.81961 0.93333 1" />
      </material>
    </visual>
    <collision>
      <origin
        xyz="0 0 0"
        rpy="0 0 0" />
      <geometry>
        <mesh
          filename="package://hubo_plugin/meshes/Body_LF2_c2_col.STL" />
      </geometry>
    </collision>
  </link>

  <joint name="LHAND_c3" type="revolute">
    <origin
      xyz="-0.04 0 0"
      rpy="0 0 0" />
    <parent
      link="Body_LF2_c2" />
    <child
      link="Body_LF2_c3" />
    <axis
      xyz="0 -1 0" />
    <limit effort="100000" velocity="100.0" lower="0" upper="1.4708" />
    <dynamics damping="0.0003" friction="0.1" />
  </joint>

  <link name="Body_LF2_c3">
    <inertial>
      <origin
        xyz="-0.00112468 3.724e-05 0.00681838"
        rpy="0 0 0" />
      <mass
        value="0.0115" />
      <inertia
        ixx="7.2e-05"
        ixy="1e-06"
        ixz="2.9e-05"
        iyy="1.67e-05"
        iyz="1e-06"
        izz="1.84e-05" />
    </inertial>
    <visual>
      <origin
        xyz="0 0 0"
        rpy="0 0 0" />
      <geometry>
        <mesh
          filename="package://hubo_plugin/meshes/Body_LF2_c3.STL" />
      </geometry>
      <material
        name="">
        <color
          rgba="0.79216 0.81961 0.93333 1" />
      </material>
    </visual>
    <collision>
      <origin
        xyz="0 0 0"
        rpy="0 0 0" />
      <geometry>
        <mesh
          filename="package://hubo_plugin/meshes/Body_LF2_c3_col.STL" />
      </geometry>
    </collision>
  </link>


<!-- RIGHT ARM -->
<!-- RIGHT ARM -->
<!-- RIGHT ARM -->
  <joint name="RSP" type="revolute">
    <origin
      xyz="0 -0.242 0.253"
      rpy="0 0 0" />
    <parent
      link="Body_TORSO" />
    <child
      link="Body_RSP" />
    <axis
      xyz="0 1 0" />
    <limit effort="10000000" velocity="100.0" lower="-5" upper="5" />
    <dynamics damping="15" friction="2" />
  </joint>

  <link name="Body_RSP">
    <inertial>
      <origin
        xyz="0.015596 0.052409 0"
        rpy="0 0 0" />
      <mass
        value="1.6" />
      <inertia
        ixx="0.005195"
        ixy="-0.001333"
        ixz="1e-08"
        iyy="0.004409"
        iyz="-1e-08"
        izz="0.007234" />
    </inertial>
    <visual>
      <origin
        xyz="0 0 0"
        rpy="0 0 0" />
      <geometry>
        <mesh
          filename="package://hubo_plugin/meshes/Body_RSP.STL" />
      </geometry>
      <material
        name="">
        <color
          rgba="0.79216 0.81961 0.93333 1" />
      </material>
    </visual>
    <collision>
      <origin
        xyz="0 0 0"
        rpy="0 0 0" />
      <geometry>
        <mesh
          filename="package://hubo_plugin/meshes/Body_RSP_col.STL" />
      </geometry>
    </collision>
  </link>

  <joint name="RSR" type="revolute">
    <origin
      xyz="0 0 0"
      rpy="0 0 0" />
    <parent
      link="Body_RSP" />
    <child
      link="Body_RSR" />
    <axis
      xyz="1 0 0" />
    <limit effort="10000000" velocity="100.0" lower="-5.14" upper="5.14" />
    <dynamics damping="15" friction="2" />
  </joint>

  <link name="Body_RSR">
    <inertial>
      <origin
        xyz="-0.003104 -0.000106 -0.013013"
        rpy="0 0 0" />
      <mass
        value="1.427" />
      <inertia
        ixx="0.003163"
        ixy="-6e-06"
        ixz="-0.000211"
        iyy="0.003689"
        iyz="-1e-08"
        izz="0.001909" />
    </inertial>
    <visual>
      <origin
        xyz="0 0 0"
        rpy="0 0 0" />
      <geometry>
        <mesh
          filename="package://hubo_plugin/meshes/Body_RSR.STL" />
      </geometry>
      <material
        name="">
        <color
          rgba="0.79216 0.81961 0.93333 1" />
      </material>
    </visual>
    <collision>
      <origin
        xyz="0 0 0"
        rpy="0 0 0" />
      <geometry>
        <mesh
          filename="package://hubo_plugin/meshes/Body_RSR_col.STL" />
      </geometry>
    </collision>
  </link>

  <joint name="RSY"
    type="revolute">
    <origin
      xyz="0 0 0"
      rpy="0 0 0" />
    <parent
      link="Body_RSR" />
    <child
      link="Body_RSY" />
    <axis
      xyz="0 0 1" />
    <limit effort="10000000" velocity="100.0" lower="-5" upper="5" />
    <dynamics damping="5" friction="2" />
  </joint>

  <link name="Body_RSY">
    <inertial>
      <origin
        xyz="0.035284 0.242 -0.87969"
        rpy="0 0 0" />
      <mass
        value="2.35838" />
      <inertia
        ixx="0.024139"
        ixy="0.000334"
        ixz="-0.003948"
        iyy="0.024861"
        iyz="-0.001103"
        izz="0.003447" />
    </inertial>
    <visual>
      <origin
        xyz="0 0 0"
        rpy="0 0 0" />
      <geometry>
        <mesh
          filename="package://hubo_plugin/meshes/Body_RSY.STL" />
      </geometry>
      <material
        name="">
        <color
          rgba="0.79216 0.81961 0.93333 1" />
      </material>
    </visual>
    <collision>
      <origin
        xyz="0 0 0"
        rpy="0 0 0" />
      <geometry>
        <mesh
          filename="package://hubo_plugin/meshes/Body_RSY_col.STL" />
      </geometry>
    </collision>
  </link>

  <joint name="REB" type="revolute">
    <origin
      xyz="0.035 0 -0.35"
      rpy="0 0 0" />
    <parent
      link="Body_RSY" />
    <child
      link="Body_REB" />
    <axis
      xyz="0 1 0" />
    <limit effort="10000000" velocity="100.0" lower="-5" upper="5" />
    <dynamics damping="8" friction="2" />
  </joint>

  <link name="Body_REB">
    <inertial>
      <origin
        xyz="-0.019775 -0.004924 -0.041836"
        rpy="0 0 0" />
      <mass
        value="0.409464" />
      <inertia
        ixx="0.001031"
        ixy="-4e-05"
        ixz="0.000277"
        iyy="0.001163"
        iyz="-8.5e-05"
        izz="0.00056" />
    </inertial>
    <visual>
      <origin
        xyz="0 0 0"
        rpy="0 0 0" />
      <geometry>
        <mesh
          filename="package://hubo_plugin/meshes/Body_REB.STL" />
      </geometry>
      <material
        name="">
        <color
          rgba="0.79216 0.81961 0.93333 1" />
      </material>
    </visual>
    <collision>
      <origin
        xyz="0 0 0"
        rpy="0 0 0" />
      <geometry>
        <mesh
          filename="package://hubo_plugin/meshes/Body_REB_col.STL" />
      </geometry>
    </collision>
  </link>

  <joint name="RWY" type="revolute">
    <origin
      xyz="-0.035 0 -0.34"
      rpy="0 0 0" />
    <parent
      link="Body_REB" />
    <child
      link="Body_RWY" />
    <axis
      xyz="0 0 1" />
    <limit effort="10000000" velocity="100.0" lower="-5" upper="5" />
    <dynamics damping="0.8" friction="50" />
  </joint>

  <link name="Body_RWY">
    <inertial>
      <origin
        xyz="5.4e-05 -0.001779 0.134651"
        rpy="0 0 0" />
      <mass
        value="1.47" />
      <inertia
        ixx="0.01302"
        ixy="1e-05"
        ixz="4e-05"
        iyy="0.012803"
        iyz="0.000388"
        izz="0.000862" />
    </inertial>
    <visual>
      <origin
        xyz="0 0 0"
        rpy="0 0 0" />
      <geometry>
        <mesh
          filename="package://hubo_plugin/meshes/Body_RWY.STL" />
      </geometry>
      <material
        name="">
        <color
          rgba="0.79216 0.81961 0.93333 1" />
      </material>
    </visual>
    <collision>
      <origin
        xyz="0 0 0"
        rpy="0 0 0" />
      <geometry>
        <mesh
          filename="package://hubo_plugin/meshes/Body_RWY_col.STL" />
      </geometry>
    </collision>
  </link>

  <joint name="RWP" type="revolute">
    <origin
      xyz="0 0 0"
      rpy="0 0 0" />
    <parent
      link="Body_RWY" />
    <child
      link="Body_RWP" />
    <axis
      xyz="0 1 0" />
    <limit effort="10000000" velocity="100.0" lower="-5" upper="5" />
    <dynamics damping="0.1" friction="0.2" />
  </joint>

  <link name="Body_RWP">
    <inertial>
      <origin
        xyz="1.7e-05 -0.011876 -0.003359"
        rpy="0 0 0" />
      <mass
        value="0.158865" />
      <inertia
        ixx="7.2e-04"
        ixy="-1e-06"
        ixz="1e-06"
        iyy="6.5e-04"
        iyz="-6e-05"
        izz="6.5e-04" />
    </inertial>
    <visual>
      <origin
        xyz="0 0 0"
        rpy="0 0 0" />
      <geometry>
        <mesh
          filename="package://hubo_plugin/meshes/Body_RWP.STL" />
      </geometry>
      <material
        name="">
        <color
          rgba="0.79216 0.81961 0.93333 1" />
      </material>
    </visual>
    <collision>
      <origin
        xyz="0 0 0"
        rpy="0 0 0" />
      <geometry>
        <mesh
          filename="package://hubo_plugin/meshes/Body_RWP_col.STL" />
      </geometry>
    </collision>
  </link>


  <joint name="RWFT" type="prismatic">
    <origin
      xyz="0 0 -0.0326"
      rpy="0 0 0" />
    <parent
      link="Body_RWP" />
    <child
      link="Body_RWFT" />
    <axis
      xyz="0 0 1" />
    <limit effort="1000000" velocity="1.0" lower="-0" upper="0" />
    <dynamics damping="1" friction="1" />
  </joint>

  <gazebo reference = "RWFT">
    <provide_feedback> true </provide_feedback>
    <physics>
      <ode>
        <provide_feedback>true</provide_feedback>
      </ode>
    </physics>
  </gazebo>


  <link name="Body_RWFT">
    <inertial>
      <origin
        xyz="-1.2e-05 3e-06 -0.017752"
        rpy="0 0 0" />
      <mass
        value="0.016659" />
      <inertia
        ixx="2e-05"
        ixy="-1e-06"
        ixz="1e-06"
        iyy="1.85e-05"
        iyz="-1e-06"
        izz="3.33e-05" />
    </inertial>
    <visual>
      <origin
        xyz="0 0 0"
        rpy="0 -0 0" />
      <geometry>
        <mesh
          filename="package://hubo_plugin/meshes/Body_RWFT.STL" />
      </geometry>
      <material
        name="">
        <color
          rgba="0.79216 0.81961 0.93333 1" />
      </material>
    </visual>
    <collision>
      <origin
        xyz="0 0 0"
        rpy="0 -0 0" />
      <geometry>
        <mesh
          filename="package://hubo_plugin/meshes/Body_RWFT_col.STL" />
      </geometry>
    </collision>

      <sensor name='FT_RWFT' type='contact'>
        <contact>
          <collision>Body_RWFT_collision</collision>
        </contact>
      </sensor>

  </link>



  <joint name="RWY2" type="revolute">
    <origin
      xyz="0 0 0.0326"
      rpy="0 0 0" />
    <parent
      link="Body_RWFT" />
    <child
      link="Body_RF1" />
    <axis
      xyz="0 0 1" />
    <limit effort="10000000" velocity="100.0" lower="-5" upper="5" />
    <dynamics damping="0.1" friction="1" />
  </joint>

  <link name="Body_RF1">
    <inertial>
      <origin
        xyz="0 0 0"
        rpy="0 -0 0" />
      <mass value="0.894667" />
      <inertia
        ixx="0.00087045"
        ixy="1.448e-05"
        ixz="-1.064e-05"
        iyy="0.00103972"
        iyz="7.89e-06"
        izz="0.00095329" />
    </inertial>
    <visual>
      <origin
        xyz="0 0 0"
        rpy="0 0 0" />
      <geometry>
        <mesh
          filename="package://hubo_plugin/meshes/Body_RF1.STL" />
      </geometry>
      <material
        name="">
        <color
          rgba="0.79216 0.81961 0.93333 1" />
      </material>
    </visual>
    <collision>
      <origin
        xyz="0 0 0"
        rpy="0 0 0" />
      <geometry>
        <mesh
          filename="package://hubo_plugin/meshes/Body_RF1_col.STL" />
      </geometry>
    </collision>
  </link>


<!-- RIGHT HAND -->
<!-- RIGHT HAND -->
<!-- RIGHT HAND -->
  <joint name="RHAND_a1" type="revolute">
    <origin
      xyz="0.02498 -0.0232 -0.1471"
      rpy="0 0 0" />
    <parent
      link="Body_RF1" />
    <child
      link="Body_RF2_a1" />
    <axis
      xyz="0 1 0" />
    <limit effort="10000000" velocity="100.0" lower="0" upper="1.4708" />
    <dynamics damping="0.0003" friction="0.1" />
  </joint>

  <link name="Body_RF2_a1">
    <inertial>
      <origin
        xyz="-0.0228526 -0.00016373 -0.0095261"
        rpy="0 0 0" />
      <mass
        value="0.038683" />
      <inertia
        ixx="1.143e-04"
        ixy="7e-06"
        ixz="-6.53e-05"
        iyy="2.17e-04"
        iyz="-1e-05"
        izz="1.314e-04" />
    </inertial>
    <visual>
      <origin
        xyz="0 0 0"
        rpy="0 0 0" />
      <geometry>
        <mesh
          filename="package://hubo_plugin/meshes/Body_RF2_a1.STL" />
      </geometry>
      <material
        name="">
        <color
          rgba="0.79216 0.81961 0.93333 1" />
      </material>
    </visual>
    <collision>
      <origin
        xyz="0 0 0"
        rpy="0 0 0" />
      <geometry>
        <mesh
          filename="package://hubo_plugin/meshes/Body_RF2_a1_col.STL" />
      </geometry>
    </collision>
  </link>

  <joint name="RHAND_a2" type="revolute">
    <origin
      xyz="0.03889 0 -0.0388"
      rpy="0 0.7854 0" />
    <parent
      link="Body_RF2_a1" />
    <child
      link="Body_RF2_a2" />
    <axis
      xyz="0 1 0" />
    <limit effort="100000" velocity="1.0" lower="0" upper="1.4708" />
    <dynamics damping="0.0003" friction="0.1" />
  </joint>

  <link name="Body_RF2_a2">
    <inertial>
      <origin
        xyz="0.0183473 -5.73e-06 0.00742064"
        rpy="0 0 0" />
      <mass
        value="0.021949" />
      <inertia
        ixx="2.31e-05"
        ixy="9e-06"
        ixz="-4.6e-06"
        iyy="7.09e-05"
        iyz="-5e-06"
        izz="6.69e-05" />
    </inertial>
    <visual>
      <origin
        xyz="0 0 0"
        rpy="0 0 0" />
      <geometry>
        <mesh
          filename="package://hubo_plugin/meshes/Body_RF2_a2.STL" />
      </geometry>
      <material
        name="">
        <color
          rgba="0.79216 0.81961 0.93333 1" />
      </material>
    </visual>
    <collision>
      <origin
        xyz="0 0 0"
        rpy="0 0 0" />
      <geometry>
        <mesh
          filename="package://hubo_plugin/meshes/Body_RF2_a2_col.STL" />
      </geometry>
    </collision>
  </link>

  <joint name="RHAND_a3" type="revolute">
    <origin
      xyz="0.04 0 0"
      rpy="0 0 0" />
    <parent
      link="Body_RF2_a2" />
    <child
      link="Body_RF2_a3" />
    <axis
      xyz="0 1 0" />
    <limit effort="10000000" velocity="100.0" lower="0" upper="1.4708" />
    <dynamics damping="0.0003" friction="0.1" />
  </joint>

  <link name="Body_RF2_a3">
    <inertial>
      <origin
        xyz="0.00112468 -3.724e-05 0.00681838"
        rpy="0 0 0" />
      <mass
        value="0.0115" />
      <inertia
        ixx="7.2e-05"
        ixy="1e-06"
        ixz="2.9e-05"
        iyy="1.67e-05"
        iyz="1e-06"
        izz="1.84e-05" />
    </inertial>
    <visual>
      <origin
        xyz="0 0 0"
        rpy="0 0 0" />
      <geometry>
        <mesh
          filename="package://hubo_plugin/meshes/Body_RF2_a3.STL" />
      </geometry>
      <material
        name="">
        <color
          rgba="0.79216 0.81961 0.93333 1" />
      </material>
    </visual>
    <collision>
      <origin
        xyz="0 0 0"
        rpy="0 0 0" />
      <geometry>
        <mesh
          filename="package://hubo_plugin/meshes/Body_RF2_a3_col.STL" />
      </geometry>
    </collision>
  </link>


  <joint name="RHAND_b1" type="revolute">
    <origin
      xyz="0.02498 0.023 -0.1471"
      rpy="0 0 0" />
    <parent
      link="Body_RF1" />
    <child
      link="Body_RF2_b1" />
    <axis
      xyz="0 1 0" />
    <limit effort="10000000" velocity="100.0" lower="0" upper="1.4708" />
    <dynamics damping="0.0003" friction="0.1" />
  </joint>

  <link name="Body_RF2_b1">
    <inertial>
      <origin
        xyz="-0.0228526 -0.00016373 -0.0095261"
        rpy="0 0 0" />
      <mass
        value="0.038683" />
      <inertia
        ixx="1.143e-04"
        ixy="7e-06"
        ixz="-6.53e-05"
        iyy="2.17e-04"
        iyz="-1e-05"
        izz="1.314e-04" />
    </inertial>
    <visual>
      <origin
        xyz="0 0 0"
        rpy="0 0 0" />
      <geometry>
        <mesh
          filename="package://hubo_plugin/meshes/Body_RF2_b1.STL" />
      </geometry>
      <material
        name="">
        <color
          rgba="0.79216 0.81961 0.93333 1" />
      </material>
    </visual>
    <collision>
      <origin
        xyz="0 0 0"
        rpy="0 0 0" />
      <geometry>
        <mesh
          filename="package://hubo_plugin/meshes/Body_RF2_b1_col.STL" />
      </geometry>
    </collision>
  </link>

  <joint name="RHAND_b2" type="revolute">
    <origin
      xyz="0.03889 0 -0.0388"
      rpy="0 0.7854 0" />
    <parent
      link="Body_RF2_b1" />
    <child
      link="Body_RF2_b2" />
    <axis
      xyz="0 1 0" />
    <limit effort="10000000" velocity="100.0" lower="0" upper="1.4708" />
    <dynamics damping="0.0003" friction="0.1" />
  </joint>

  <link name="Body_RF2_b2">
    <inertial>
      <origin
        xyz="0.0183473 -5.73e-06 0.00742064"
        rpy="0 0 0" />
      <mass
        value="0.021949" />
      <inertia
        ixx="2.31e-05"
        ixy="9e-06"
        ixz="-4.6e-06"
        iyy="7.09e-05"
        iyz="-5e-06"
        izz="6.69e-05" />
    </inertial>
    <visual>
      <origin
        xyz="0 0 0"
        rpy="0 0 0" />
      <geometry>
        <mesh
          filename="package://hubo_plugin/meshes/Body_RF2_b2.STL" />
      </geometry>
      <material
        name="">
        <color
          rgba="0.79216 0.81961 0.93333 1" />
      </material>
    </visual>
    <collision>
      <origin
        xyz="0 0 0"
        rpy="0 0 0" />
      <geometry>
        <mesh
          filename="package://hubo_plugin/meshes/Body_RF2_b2_col.STL" />
      </geometry>
    </collision>
  </link>

  <joint name="RHAND_b3" type="revolute">
    <origin
      xyz="0.04 0 0"
      rpy="0 0 0" />
    <parent
      link="Body_RF2_b2" />
    <child
      link="Body_RF2_b3" />
    <axis
      xyz="0 1 0" />
    <limit effort="10000000" velocity="100.0" lower="0" upper="1.4708" />
    <dynamics damping="0.0003" friction="0.1" />
  </joint>

  <link name="Body_RF2_b3">
    <inertial>
      <origin
        xyz="0.00112468 -3.724e-05 0.00681838"
        rpy="0 0 0" />
      <mass
        value="0.0115" />
      <inertia
        ixx="7.2e-05"
        ixy="1e-06"
        ixz="2.9e-05"
        iyy="1.67e-05"
        iyz="1e-06"
        izz="1.84e-05" />
    </inertial>
    <visual>
      <origin
        xyz="0 0 0"
        rpy="0 0 0" />
      <geometry>
        <mesh
          filename="package://hubo_plugin/meshes/Body_RF2_b3.STL" />
      </geometry>
      <material
        name="">
        <color
          rgba="0.79216 0.81961 0.93333 1" />
      </material>
    </visual>
    <collision>
      <origin
        xyz="0 0 0"
        rpy="0 0 0" />
      <geometry>
        <mesh
          filename="package://hubo_plugin/meshes/Body_RF2_b3_col.STL" />
      </geometry>
    </collision>
  </link>

  <joint name="RHAND_c1" type="revolute">
    <origin
      xyz="-0.02502 0 -0.1471"
      rpy="0 0 0 " />
    <parent
      link="Body_RF1" />
    <child
      link="Body_RF2_c1" />
    <axis
      xyz="0 -1 0" />
    <limit effort="10000000" velocity="100.0" lower="0" upper="1.4708" />
    <dynamics damping="0.0003" friction="0.1" />
  </joint>

  <link name="Body_RF2_c1">
    <inertial>
      <origin
        xyz="-0.0228526 0.00016373 -0.0095261"
        rpy="0 0 0" />
      <mass
        value="0.038683" />
      <inertia
        ixx="1.143e-04"
        ixy="7e-06"
        ixz="-6.53e-05"
        iyy="2.17e-04"
        iyz="-1e-05"
        izz="1.314e-04" />
    </inertial>
    <visual>
      <origin
        xyz="0 0 0"
        rpy="0 0 0" />
      <geometry>
        <mesh
          filename="package://hubo_plugin/meshes/Body_RF2_c1.STL" />
      </geometry>
      <material
        name="">
        <color
          rgba="0.79216 0.81961 0.93333 1" />
      </material>
    </visual>
    <collision>
      <origin
        xyz="0 0 0"
        rpy="0 0 0" />
      <geometry>
        <mesh
          filename="package://hubo_plugin/meshes/Body_RF2_c1_col.STL" />
      </geometry>
    </collision>
  </link>

  <joint name="RHAND_c2" type="revolute">
    <origin
      xyz="-0.03889 0 -0.0388"
      rpy="0 -0.7854 0" />
    <parent
      link="Body_RF2_c1" />
    <child
      link="Body_RF2_c2" />
    <axis
      xyz="0 -1 0" />
    <limit effort="10000000" velocity="100.0" lower="0" upper="1.4708" />
    <dynamics damping="0.0003" friction="0.1" />
  </joint>

  <link name="Body_RF2_c2">
    <inertial>
      <origin
        xyz="-0.0183473 5.73e-06 0.00742064"
        rpy="0 0 0" />
      <mass
        value="0.021949" />
      <inertia
        ixx="2.31e-05"
        ixy="9e-06"
        ixz="-4.6e-06"
        iyy="7.09e-05"
        iyz="-5e-06"
        izz="6.69e-05" />
    </inertial>
    <visual>
      <origin
        xyz="0 0 0"
        rpy="0 0 0" />
      <geometry>
        <mesh
          filename="package://hubo_plugin/meshes/Body_RF2_c2.STL" />
      </geometry>
      <material
        name="">
        <color
          rgba="0.79216 0.81961 0.93333 1" />
      </material>
    </visual>
    <collision>
      <origin
        xyz="0 0 0"
        rpy="0 0 0" />
      <geometry>
        <mesh
          filename="package://hubo_plugin/meshes/Body_RF2_c2_col.STL" />
      </geometry>
    </collision>
  </link>

  <joint name="RHAND_c3" type="revolute">
    <origin
      xyz="-0.04 0 0"
      rpy="0 0 0" />
    <parent
      link="Body_RF2_c2" />
    <child
      link="Body_RF2_c3" />
    <axis
      xyz="0 -1 0" />
    <limit effort="10000000" velocity="100.0" lower="0" upper="1.4708" />
    <dynamics damping="0.0003" friction="0.1" />
  </joint>

  <link name="Body_RF2_c3">
    <inertial>
      <origin
        xyz="-0.00112468 3.724e-05 0.00681838"
        rpy="0 0 0" />
      <mass
        value="0.0115" />
      <inertia
        ixx="7.2e-05"
        ixy="1e-06"
        ixz="2.9e-05"
        iyy="1.67e-05"
        iyz="1e-06"
        izz="1.84e-05" />
    </inertial>
    <visual>
      <origin
        xyz="0 0 0"
        rpy="0 0 0" />
      <geometry>
        <mesh
          filename="package://hubo_plugin/meshes/Body_RF2_c3.STL" />
      </geometry>
      <material
        name="">
        <color
          rgba="0.79216 0.81961 0.93333 1" />
      </material>
    </visual>
    <collision>
      <origin
        xyz="0 0 0"
        rpy="0 0 0" />
      <geometry>
        <mesh
          filename="package://hubo_plugin/meshes/Body_RF2_c3_col.STL" />
      </geometry>
    </collision>
  </link>



<!-- RIGHT HAND gazebo reference-->

  <gazebo reference="Body_RF2_a1">
    <mu1 value="1.0"/>
    <mu2 value="1.0"/>
    <kp value="10000000.0"/>
    <kd value="1.0"/>
    <fdir1 value="1 0 0"/>
    <min_depth value = "0.001"/>
    <max_vel value = "0.1"/>
    <turnGravityOff>false</turnGravityOff>
  </gazebo>

  <gazebo reference="Body_RF2_a2">
    <mu1 value="1.0"/>
    <mu2 value="1.0"/>
    <kp value="10000000.0"/>
    <kd value="1.0"/>
    <fdir1 value="1 0 0"/>
    <min_depth value = "0.001"/>
    <max_vel value = "0.1"/>
    <turnGravityOff>false</turnGravityOff>
  </gazebo>

  <gazebo reference="Body_RF2_a3">
    <mu1 value="1.0"/>
    <mu2 value="1.0"/>
    <kp value="10000000.0"/>
    <kd value="1.0"/>
    <fdir1 value="1 0 0"/>
    <min_depth value = "0.001"/>
    <max_vel value = "0.1"/>
    <turnGravityOff>false</turnGravityOff>
  </gazebo>

  <gazebo reference="Body_RF2_b1">
    <mu1 value="1.0"/>
    <mu2 value="1.0"/>
    <kp value="10000000.0"/>
    <kd value="1.0"/>
    <fdir1 value="1 0 0"/>
    <min_depth value = "0.001"/>
    <max_vel value = "0.1"/>
    <turnGravityOff>false</turnGravityOff>
  </gazebo>

  <gazebo reference="Body_RF2_b2">
    <mu1 value="1.0"/>
    <mu2 value="1.0"/>
    <kp value="10000000.0"/>
    <kd value="1.0"/>
    <fdir1 value="1 0 0"/>
    <min_depth value = "0.001"/>
    <max_vel value = "0.1"/>
    <turnGravityOff>false</turnGravityOff>
  </gazebo>

  <gazebo reference="Body_RF2_b3">
    <mu1 value="1.0"/>
    <mu2 value="1.0"/>
    <kp value="10000000.0"/>
    <kd value="1.0"/>
    <fdir1 value="1 0 0"/>
    <min_depth value = "0.001"/>
    <max_vel value = "0.1"/>
    <turnGravityOff>false</turnGravityOff>
  </gazebo>

  <gazebo reference="Body_RF2_c1">
    <mu1 value="1.0"/>
    <mu2 value="1.0"/>
    <kp value="10000000.0"/>
    <kd value="1.0"/>
    <fdir1 value="1 0 0"/>
    <min_depth value = "0.001"/>
    <max_vel value = "0.1"/>
    <turnGravityOff>false</turnGravityOff>
  </gazebo>

  <gazebo reference="Body_RF2_c2">
    <mu1 value="1.0"/>
    <mu2 value="1.0"/>
    <kp value="10000000.0"/>
    <kd value="1.0"/>
    <fdir1 value="1 0 0"/>
    <min_depth value = "0.001"/>
    <max_vel value = "0.1"/>
    <turnGravityOff>false</turnGravityOff>
  </gazebo>

  <gazebo reference="Body_RF2_c3">
    <mu1 value="1.0"/>
    <mu2 value="1.0"/>
    <kp value="10000000.0"/>
    <kd value="1.0"/>
    <fdir1 value="1 0 0"/>
    <min_depth value = "0.001"/>
    <max_vel value = "0.1"/>
    <turnGravityOff>false</turnGravityOff>
  </gazebo>


  <!--======================= Base ========================-->
  <!--======================= Base ========================-->
  <!--======================= Base ========================-->

  <!-- Body WHBase Link -->
  <link name="Body_WHBase_link">
    <collision>
      <origin xyz = "0 0 0" rpy = "0 0 0" />
      <geometry>
        <mesh filename="package://hubo_plugin/meshes/OmniWheelBase_col.STL"/>
      </geometry>
    </collision>

    <visual>
      <origin xyz="0 0 0" rpy="0 0 0"/>
      <geometry>
        <mesh filename="package://hubo_plugin/meshes/OmniWheelBase.STL"/>
      </geometry>      
      <material name="">
        <color rgba="0.79216 0.81961 0.93333 1" />
      </material>
    </visual>

    <inertial>
      <origin xyz="0 0 0" rpy="0 0 0"/>
      <mass value="44.86503"/>
      <inertia ixx="3978968822.59e-9"
               ixy="-345397.42e-9"
               ixz="-8497104.96e-9"
               iyy="3974350833.57e-9"
               iyz="1236233.78e-9"
               izz="958764103.50e-9"/>
    </inertial>
  </link>

<!--VISION HEAD-->
<!--VISION HEAD-->
<!--VISION HEAD-->

  <joint name="Body_head_joint" type="fixed">
    <axis xyz="0 0 1" />
    <origin xyz="0 0 0.318" rpy="0 0 0"/>
    <parent link="Body_TORSO"/>
    <child link="Body_vision"/>
  </joint>

  <link name="Body_vision">
    <collision>
      <origin xyz="0.04419 0 0.054" rpy="0 0 0"/>
      <geometry>
	<mesh
          filename="package://hubo_plugin/meshes/ASM_VISION_col.STL" />
      </geometry>
    </collision>

    <visual>
      <origin xyz="0.04419 0 0.054" rpy="0 0 0"/>
      <geometry>
	<mesh
          filename="package://hubo_plugin/meshes/ASM_VISION.STL" />
      </geometry>
      <material name="">
        <color rgba="0.79216 0.81961 0.93333 1" />
      </material>
    </visual>

    <inertial>
      <mass value="1e-5" />
      <origin xyz="0 0 0" rpy="0 0 0"/>
      <inertia ixx="1e-6" ixy="0" ixz="0" iyy="1e-6" iyz="0" izz="1e-6" />
    </inertial>
  </link>


  <!-- realsenseD435 RGB-D camera -->
  <joint name="Head_realsense_joint" type="fixed">
    <axis xyz="0 0 1" />
    <origin xyz="0.044 0 0.111" rpy="0 0.5235 0"/>
    <parent link="Body_vision"/>
    <child link="Head_realsense_camera"/>
  </joint>
  
  <link name="Head_realsense_camera">
    <inertial>
      <mass value="0.0001"/>
      <origin xyz="0 0 0"/>
      <inertia ixx="0.0001" ixy="0.0" ixz="0.0" iyy="0.0001" iyz="0.0" izz="0.0001"/>
    </inertial>
    <visual>
      <origin rpy="0 0 0" xyz="0 0 0"/>
      <geometry>
        <box size="0.001 0.001 0.001"/>
      </geometry>
    </visual>
  </link>
  
  <gazebo reference="Head_realsense_camera">
    <sensor type="depth" name="realsense_camera">
	  <origin xyz="0 0 0" rpy="0 0 0"/>
      <camera name="realsense_camera">
		  <update_rate>30.0</update_rate>
        <horizontal_fov>1.047</horizontal_fov>
        <image>
          <width>640</width>
          <height>480</height>
          <format>RGB_INT8</format>
        </image>
        <clip>
          <near>0.3</near>
          <far>10</far>
        </clip>
        <noise>
          <type>gaussian</type>
          <!-- Noise is sampled independently per pixel on each frame.
               That pixel's noise value is added to each of its color
               channels, which at that point lie in the range [0,1]. -->
          <mean>0.0</mean>
          <stddev>0.007</stddev>
        </noise>
      </camera>
      
      <plugin name="realsense_camera_controller" filename="libgazebo_ros_openni_kinect.so">
        <alwaysOn>true</alwaysOn>
        <updateRate>0.0</updateRate>
        
        <cameraName>mobile_hubo/realsense_camera</cameraName>
        <imageTopicName>realsense/rgb/image_raw</imageTopicName>
        <cameraInfoTopicName>realsense/rgb/camera_info</cameraInfoTopicName>
        <depthImageTopicName>realsense/depth/image_raw</depthImageTopicName>
        <depthImageCameraInfoTopicName>realsense/depth/camera_info</depthImageCameraInfoTopicName>
        <pointCloudTopicName>realsense/depth/points</pointCloudTopicName>
            
        <frameName>Head_realsense_camera</frameName>
        <hackBaseline>0.07</hackBaseline>
        <distortionK1>0.0</distortionK1>
        <distortionK2>0.0</distortionK2>
        <distortionK3>0.0</distortionK3>
        <distortionT1>0.0</distortionT1>
        <distortionT2>0.0</distortionT2>
      </plugin>
    </sensor>
  </gazebo>


  
  <!-- ZED RGB-D camera : roll is flipped upside-down-->
  <!-- ZED RGB-D camera : origin xyz needs to be revised -->

  <joint name="Head_zed_joint" type="fixed">
    <axis xyz="0 0 1" />
    <origin xyz="0.1 0 -0.028" rpy="3.14 0 0"/>
    <parent link="Body_vision"/>
    <child link="Head_zed_camera"/>
  </joint>
  
  <link name="Head_zed_camera">
    <inertial>
      <mass value="0.0001"/>
      <origin xyz="0 0 0"/>
      <inertia ixx="0.0001" ixy="0.0" ixz="0.0" iyy="0.0001" iyz="0.0" izz="0.0001"/>
    </inertial>
    <visual>
      <origin rpy="0 0 0" xyz="0 0 0"/>
      <geometry>
        <box size="0.001 0.001 0.001"/>
      </geometry>
    </visual>
  </link>
  
  <gazebo reference="Head_zed_camera">
    <sensor type="depth" name="zed_camera">
	  <pose frame="">0 0 0 0 0 0</pose>
      <camera name="zed_camera">
		  <update_rate>30.0</update_rate>
        <horizontal_fov>0.87092</horizontal_fov>
        <image>
          <width>640</width>
          <height>480</height>
          <format>B8G8R8</format>
        </image>
        <clip>
          <near>0.2</near>
          <far>20</far>
        </clip>
        <noise>
          <type>gaussian</type>
          <!-- Noise is sampled independently per pixel on each frame.
               That pixel's noise value is added to each of its color
               channels, which at that point lie in the range [0,1]. -->
          <mean>0.0</mean>
          <stddev>0.007</stddev>
        </noise>
      </camera>

      
      <plugin name="zed_camera_controller" filename="libgazebo_ros_openni_kinect.so">
        <alwaysOn>true</alwaysOn>
        <updateRate>0.0</updateRate>
        
        <cameraName>mobile_hubo/zed_camera</cameraName>
        <imageTopicName>zed/rgb/image_raw</imageTopicName>
        <cameraInfoTopicName>zed/rgb/camera_info</cameraInfoTopicName>
        <depthImageTopicName>zed/depth/image_raw</depthImageTopicName>
        <depthImageCameraInfoTopicName>zed/depth/camera_info</depthImageCameraInfoTopicName>
        <pointCloudTopicName>zed/depth/points</pointCloudTopicName>
            
        <frameName>Head_zed_camera</frameName>
        <hackBaseline>0.07</hackBaseline>
        <distortionK1>0.0</distortionK1>
        <distortionK2>0.0</distortionK2>
        <distortionK3>0.0</distortionK3>
        <distortionT1>0.0</distortionT1>
        <distortionT2>0.0</distortionT2>
      </plugin>
    </sensor>
  </gazebo>


 <!-- velodyne VLP16 lidar -->

  <joint name="Head_velodyne_joint" type="fixed">
    <axis xyz="0 0 1" />
    <origin xyz="0 0 0.036" rpy="0 0 0"/>
    <parent link="Body_vision"/>
    <child link="Head_velodyne_lidar"/>
  </joint>
  
  <link name="Head_velodyne_lidar">
    <inertial>
      <mass value="0.0001"/>
      <origin xyz="0 0 0"/>
      <inertia ixx="0.0001" ixy="0.0" ixz="0.0" iyy="0.0001" iyz="0.0" izz="0.0001"/>
    </inertial>
    <visual>
      <origin rpy="0 0 0" xyz="0 0 0"/>
      <geometry>
        <box size="0.001 0.001 0.001"/>
      </geometry>
    </visual>  
  </link>
 
  <gazebo reference="Head_velodyne_lidar">
    <sensor type="ray" name="VLP16">
	<pose frame="">0 0 0 0 0 0</pose>
		
      <visualize>false</visualize>
      <update_rate>10</update_rate>
      <ray>
        <scan>
          <horizontal>
                <samples>440</samples>
                <resolution>1</resolution>
                <min_angle>-3.14</min_angle>
                <max_angle>3.14</max_angle>
              </horizontal>
              <vertical>
                <samples>16</samples>
                <resolution>1</resolution>
                <min_angle>-15.0*3.14/180.0</min_angle>
                <max_angle> 15.0*3.14/180.0</max_angle>
              </vertical>
        </scan>
        <range>
          <min>0.50</min>
          <max>50.0</max>
          <resolution>0.01</resolution>
        </range>
        <noise>
          <type>gaussian</type>
          
          <mean>0.0</mean>
          <stddev>0.01</stddev>
        </noise>
      </ray>

      <!-- must install by sudo apt get ros-kinetic-velodyne-gazeboplugin -->

      <plugin name="laser_controller" filename="libgazebo_ros_velodyne_laser.so">
        <topicName>/mobile_hubo/lidar/velodyne_points</topicName>
        <frameName>Head_velodyne_lidar</frameName>
        <alwaysOn>true</alwaysOn>
      <updateRate>0</updateRate>
      </plugin>

    </sensor>
   </gazebo>


   
  <!-- 3DM-GX5 imu -->
  <!-- 3DM-GX5 imu pose needs revision -->

  <joint name="Head_imu_joint" type="fixed">
    <axis xyz="0 0 1" />
    <origin xyz="0 0 -0.01" rpy="0 0 0"/>
    <parent link="Body_vision"/>
    <child link="Head_imu"/>
  </joint>
  
  <link name="Head_imu"> 
    <inertial>
      <mass value="0.0001"/>
      <origin xyz="0 0 0"/>
      <inertia ixx="0.0001" ixy="0.0" ixz="0.0" iyy="0.0001" iyz="0.0" izz="0.0001"/>
    </inertial>
    <visual>
      <origin rpy="0 0 0" xyz="0 0 0"/>
      <geometry>
        <box size="0.001 0.001 0.001"/>
      </geometry>
    </visual> 
  </link>

  <gazebo reference="Head_imu">
     <gravity>true</gravity>
    <sensor name="imu_sensor" type="imu">
      <always_on>true</always_on>
      <update_rate>100</update_rate>
      <visualize>true</visualize>
      <topic>__default_topic__</topic>
      <plugin filename="libgazebo_ros_imu_sensor.so" name="imu_plugin">
        <topicName>/mobile_hubo/imu</topicName>
        <bodyName>Head_imu</bodyName>
        <updateRateHZ>10.0</updateRateHZ>
        <gaussianNoise>0.0</gaussianNoise>
        <xyzOffset>0 0 0</xyzOffset>
        <rpyOffset>0 0 0</rpyOffset>
        <frameName>imu_link</frameName>
      </plugin>
      <pose>0 0 0 0 0 0</pose>
    </sensor>
  </gazebo>


<!-- drc_plugin  -->
  <gazebo>
    <plugin name="hubo_gazebo_plugin" filename="/home/rainbow/catkin_ws/devel/lib/libhubo_gazebo_plugin.so"/>
  </gazebo>


<!-- gazebo ros control -->
<gazebo>
  <plugin name = "gazebo_ros_control" filename="libgazebo_ros_control.so">
  </plugin>
</gazebo>
 
</robot>

